## üìù Aula 05: Lan√ßando exce√ß√µes
A instru√ß√£o ``throw`` √© usada para lan√ßar uma exce√ß√£o definida pelo usu√°rio em JavaScript. Quando voc√™ lan√ßa uma exce√ß√£o, a express√£o especifica o valor da exce√ß√£o. A execu√ß√£o da fun√ß√£o atual vai parar (as instru√ß√µes ap√≥s o ``throw`` n√£o ser√£o executadas), e o controle ser√° passado para o primeiro bloco ``catch`` na pilha de chamadas. Se nenhum bloco ``catch`` existe entre as fun√ß√µes ‚Äúchamadoras‚Äù, o programa vai terminar .

Aqui est√° um exemplo de como usar a instru√ß√£o throw para lan√ßar uma exce√ß√£o:

```
$('#formulario-pedido').submit(function(evento) {
    evento.preventDefault();
    
    if($('#nome').val().length == 0) {
        throw new Error('Digite o nome');
    }
})
```

O c√≥digo verifica se o campo de entrada com o ID ``nome`` est√° vazio, verificando se o comprimento do valor √© igual a 0. Se for verdadeiro, uma exce√ß√£o √© lan√ßada usando a instru√ß√£o ``throw`` com um objeto ``Error`` contendo uma mensagem de erro.

Isso interrompe a execu√ß√£o da fun√ß√£o e passa o controle para o primeiro bloco ``catch`` na pilha de chamadas, se houver. Se nenhum bloco ``catch`` for encontrado, a exce√ß√£o ser√° propagada at√© o n√≠vel superior e exibida para o usu√°rio.

Voc√™ pode usar ``throw`` para relan√ßar uma exce√ß√£o depois de captur√°-la. Isso √© √∫til quando voc√™ deseja adicionar informa√ß√µes adicionais √† exce√ß√£o ou modificar seu comportamento antes de propag√°-la para cima na pilha de chamadas.

<br>

## ‚úÖ Question√°rio
Como disparamos um erro no JavaScript?

A- new Error(‚ÄùDescri√ß√£o do erro");

B- throw Error(‚ÄùDescri√ß√£o do erro");

C- throw new Exception("Descri√ß√£o do erro");

D- throw new Error("Descri√ß√£o do erro");

Reposta: Letra D - A instru√ß√£o throw √© usada para lan√ßar uma exce√ß√£o definida pelo usu√°rio em JavaScript. Quando voc√™ lan√ßa uma exce√ß√£o, a express√£o especifica o valor da exce√ß√£o. Voc√™ pode criar um objeto de erro usando o construtor Error e passando uma mensagem de erro como argumento. Em seguida, voc√™ pode lan√ßar o objeto de erro usando a instru√ß√£o throw. Isso interrompe a execu√ß√£o da fun√ß√£o atual e passa o controle para o primeiro bloco catch na pilha de chamadas .