## üìù Aula 04: Tratando exce√ß√µes
Tratar exce√ß√µes √© uma parte importante do desenvolvimento de qualquer aplica√ß√£o, pois permite que voc√™ lide com erros e falhas de maneira elegante, sem interromper a execu√ß√£o do programa ou exibir mensagens de erro confusas para o usu√°rio.

Existem v√°rias maneiras de tratar exce√ß√µes em JavaScript. Uma maneira comum √© usar os blocos ``try``/``catch`` para capturar erros que possam ocorrer durante a execu√ß√£o de um bloco de c√≥digo. Aqui est√° um exemplo:

```
try {
    // C√≥digo que pode lan√ßar uma exce√ß√£o
    const resultado = funcaoQuePodeLancarExcecao();
    console.log(resultado);
} catch (erro) {
    // C√≥digo para lidar com a exce√ß√£o
    console.error('Ocorreu um erro:', erro);
}
```

Neste exemplo, o c√≥digo dentro do bloco ``try`` pode lan√ßar uma exce√ß√£o. Se isso acontecer, a execu√ß√£o do bloco ``try`` ser√° interrompida e o c√≥digo dentro do bloco ``catch`` ser√° executado. O objeto erro passado para o bloco ``catch`` cont√©m informa√ß√µes sobre o ``erro`` que ocorreu.

Outra maneira de tratar exce√ß√µes √© usar promessas e encadear um m√©todo ``catch`` ao final da cadeia de promessas. Isso permite que voc√™ capture qualquer ``erro`` que possa ocorrer durante a resolu√ß√£o da promessa ou durante a execu√ß√£o de qualquer uma das fun√ß√µes passadas para os m√©todos ``then``. Aqui est√° um exemplo:

```
funcaoQueRetornaUmaPromessa()
    .then(resultado => {
        // C√≥digo para processar o resultado
        console.log(resultado);
    })
    .catch(erro => {
        // C√≥digo para lidar com o erro
        console.error('Ocorreu um erro:', erro);
    });
```

Neste exemplo, a fun√ß√£o ``funcaoQueRetornaUmaPromessa`` retorna uma promessa que pode ser resolvida com sucesso ou rejeitada com um erro. Se a promessa for resolvida com sucesso, a primeira fun√ß√£o an√¥nima passada para o m√©todo ``then`` ser√° chamada com o resultado da promessa como argumento. Se a promessa for rejeitada com um erro ou se ocorrer um erro durante a execu√ß√£o da primeira fun√ß√£o an√¥nima, a fun√ß√£o an√¥nima passada para o m√©todo ``catch`` ser√° chamada com o objeto de erro como argumento.

√â importante sempre tratar exce√ß√µes em seu c√≥digo para evitar que erros inesperados interrompam a execu√ß√£o do programa ou causem comportamentos indesejados.

<br>

### Exemplo
```
$(document).ready(function() {
    $('#cep').mask('00000-000');

    $('#btn-buscar-cep').click(function() {
        const cep = $('#cep').val();
        const endpoint = `https://viacep.com.br/ws/${cep}/json`;
        const botao = $(this);
        $(botao).find('i').addClass('d-none');
        $(botao).find('span').removeClass('d-none')

        fetch(endpoint)
            .then(function(resposta) {
                return resposta.json();
            })
            .then(function(json) {
                const logradouro = json.logradouro;
                const bairro = json.bairro;
                const cidade = json.localidade
                const estado = json.uf

                const endereco = `${logradouro}, ${bairro} - ${cidade} / ${estado}`
                $('#endereco').val(endereco)
            })
            .catch(function(erro) {
                alert("ocorreu um erro ao buscar o endere√ßo, tente novamente mais tarde");
            })
            .finally(function() {
                setTimeout(function() {
                    $(botao).find('i').removeClass('d-none');
                    $(botao).find('span').addClass('d-none');
                }, 1000);
            })
    })
})
```

Este c√≥digo √© uma vers√£o modificada do c√≥digo anterior que usa a Fetch API para fazer uma requisi√ß√£o AJAX para buscar informa√ß√µes sobre um CEP e preencher um campo de endere√ßo com os dados retornados. Ele tamb√©m adiciona tratamento de exce√ß√µes para lidar com erros que possam ocorrer durante a requisi√ß√£o.

O c√≥digo adiciona um m√©todo ``catch`` ao final da cadeia de promessas para lidar com quaisquer erros que possam ocorrer durante a requisi√ß√£o ou o processamento da resposta. A fun√ß√£o an√¥nima passada para o m√©todo ``catch`` √© chamada com o objeto de erro como argumento. Neste caso, ela exibe um alerta informando ao usu√°rio que ocorreu um erro ao buscar o endere√ßo.

Por fim, o c√≥digo adiciona um m√©todo ``finally`` ao final da cadeia de promessas para executar c√≥digo independentemente de a promessa ter sido resolvida ou rejeitada. A fun√ß√£o an√¥nima passada para o m√©todo ``finally`` usa o m√©todo setTimeout para agendar uma fun√ß√£o para ser chamada ap√≥s 1 segundo (1000 milissegundos). Essa fun√ß√£o alterna novamente a visibilidade dos elementos filhos do bot√£o clicado (um √≠cone e um elemento span) usando os m√©todos find, addClass e removeClass do jQuery.

<br>

## ‚úÖ Question√°rio
Qual bloco ser√° executado caso ocorra um erro na execu√ß√£o do nosso c√≥digo JavaScript?

A- error;

B- catch;

C- finally;

D- try;

Reposta: Letra B - Se ocorrer um erro durante a execu√ß√£o de um bloco de c√≥digo JavaScript dentro de um bloco try, o c√≥digo dentro do bloco catch correspondente ser√° executado. O bloco catch permite que voc√™ lide com exce√ß√µes de maneira elegante, sem interromper a execu√ß√£o do programa ou exibir mensagens de erro confusas para o usu√°rio.